Workbook

Sheet Summary
A1: Kusina Kode — Mobile Stress Test
A2: Run 5 Oct 2026 on an Android emulator. Blue = measured value, black = formula.
A4: Device | B4: Android emulator 'Medium Phone', Android 16, 2 GB RAM (debug build); and a real vivo V17 Pro, Android 12, Snapdragon 675, 8 GB RAM (release 1.26)
A5: App build | B5: Kusina Kode 1.25 debug build (slower than the release APK players install)
A6: Account | B6: Test player account (Chef nick), logged in
A7: Server impact | B7: None. Read-only scenario: navigation, scrolling, typing and erasing letters. No guess was submitted; no purchase, spin or sign-up.
A8: Tools | B8: Android dumpsys gfxinfo (frames), dumpsys meminfo (memory), am start -W (startup), dropbox ANR reports
A9: Scenario | B9: Five screens (Home, Game Map, Learn + dish page, Pantry, Puzzle board), each measured on its own; then five full loops through all of them.
A11: Key results
A12: Cold start (quiet phone) | B12: ='Startup'!C12
A13: Warm start | B13: ='Startup'!C13
A14: Janky frames, sustained run | B14: ='Sustained'!B5
A15: Memory trend over the sustained run | B15: ='Sustained'!C21
A16: Crashes / freezes during play | B16: ='Sustained'!B11
A17: Startup freezes found | B17: 2 (both right after the emulator booted) — see 'Startup freezes'
A19: Limitations | B19: The emulator gives worst-case startup and memory figures, but not smoothness (it borrows the laptop's processor and graphics). Frame rates come from the real phone. One mid-range phone was tested; a budget phone would show more strain.
A21: Real phone (vivo V17 Pro, release 1.26)
A22: Cold start, real phone | B22: ='Real phone'!B19
A23: Game Map janky frames, real phone | B23: ='Real phone'!E24
A24: Sustained janky frames, real phone | B24: ='Real phone'!B41
A25: Memory trend, real phone | B25: ='Real phone'!C54
A27: Server (read-only load, live)
A28: Errors from 5 to 40 players | B28: ='Server load'!E9
A29: Average response at 40 players (s) | B29: ='Server load'!F8
A30: Peak database load (DTU %) | B30: =MAX('Azure metrics'!G5:G30)
A31: Not yet tested | B31: Purchases, spins and claims under load (writes to the reward chain): waiting for a test copy of the server (option A).
A33: Correction | B33: Earlier drafts called the emulator a worst case. For startup and memory it is; for smoothness it is not, because the emulator uses the laptop's processor and graphics. The real-phone sheet is the one to cite for frame rates.

Sheet Startup
A1: App startup time (ms)
A2: am start -W TotalTime. Cold = app fully closed. Warm = brought back from the background.
A4: Run | B4: Cold — before fix | C4: Cold — after fix | D4: Warm — before fix | E4: Warm — after fix
A5: Run 1 | B5: 2824 | C5: 3089 | D5: 127 | E5: 152
A6: Run 2 | B6: 2609 | C6: 2463 | D6: 146 | E6: 142
A7: Run 3 | B7: 2516 | C7: 2439 | D7: 170 | E7: 139
A8: Run 4 | B8: 2389 | C8: 2671 | D8: 160 | E8: 165
A9: Run 5 | B9: 2801 | C9: 2439 | D9: 84 | E9: 150
A10: Average | B10: =AVERAGE(B5:B9) | C10: =AVERAGE(C5:C9) | D10: =AVERAGE(D5:D9) | E10: =AVERAGE(E5:E9)
A11: Fastest | B11: =MIN(B5:B9) | C11: =MIN(C5:C9) | D11: =MIN(D5:D9) | E11: =MIN(E5:E9)
A12: Cold start, after fix (avg) | B12: =MAX(B5:B9) | C12: =TEXT(C10/1000,"0.0")&" s" | D12: =MAX(D5:D9) | E12: =MAX(E5:E9)
A13: Warm start, after fix (avg) | C13: =TEXT(E10/1000,"0.00")&" s"
A16: Cold start with the CPU maxed out (six busy loops inside the emulator)
A17: Run | B17: Old startup code | C17: Fixed startup code
A18: Run 1 | B18: 5931 | C18: 7611
A19: Run 2 | B19: 6086 | C19: 5928
A20: Run 3 | B20: 6482 | C20: 6183
A21: Average | B21: =AVERAGE(B18:B20) | C21: =AVERAGE(C18:C20)
A22: Freezes (ANR) during these runs | B22: 0 | C22: 0
A24: Reading: on a quiet phone startup is unchanged by the fix (the noise between runs is larger than any difference). Maxing out the CPU did not reproduce the freeze in either version, so this test cannot prove the fix prevents it; see 'Startup freezes'.

Sheet Real phone
A1: Real phone: vivo V17 Pro, release build 1.26
A2: Same read-only scenario as the emulator. Blue = measured, black = formula.
A4: Phone | B4: vivo 1910 (vivo V17 Pro)
A5: Android | B5: 12 (API 31)
A6: Chip | B6: Qualcomm SM6150 (Snapdragon 675)
A7: RAM | B7: 8 GB (MemTotal 7752860 kB)
A8: Screen | B8: 1080 x 2400, density 480, 60 Hz
A9: App | B9: Kusina Kode 1.26 release build (versionCode 27), installed from the v1.26 release
A10: Account | B10: Chef Mau (logged in)
A12: Startup (ms)
A13: Run | B13: Cold start | C13: Warm start
A14: Run 1 | B14: 703 | C14: 139
A15: Run 2 | B15: 782 | C15: 155
A16: Run 3 | B16: 772 | C16: 146
A17: Run 4 | B17: 723 | C17: 146
A18: Run 5 | B18: 735 | C18: 152
A19: Average | B19: =AVERAGE(B14:B18) | C19: =AVERAGE(C14:C18)
A21: Per screen
A22: Screen | B22: Seconds | C22: Frames | D22: Janky frames | E22: Janky % | F22: Median frame (ms) | G22: 90th pct (ms) | H22: 95th pct (ms) | I22: 99th pct (ms) | J22: Slow UI-thread frames | K22: Memory (PSS, MB)
A23: Home | B23: 28 | C23: 961 | D23: 353 | E23: =D23/C23 | F23: 24 | G23: 34 | H23: 34 | I23: 46 | J23: 75 | K23: =207515/1024
A24: Game Map | B24: 97 | C24: 4526 | D24: 4268 | E24: =D24/C24 | F24: 38 | G24: 48 | H24: 53 | I24: 65 | J24: 3531 | K24: =379913/1024
A25: Learn + dish page | B25: 72 | C25: 1502 | D25: 274 | E25: =D25/C25 | F25: 23 | G25: 31 | H25: 38 | I25: 61 | J25: 186 | K25: =521665/1024
A26: Pantry | B26: 44 | C26: 1772 | D26: 1487 | E26: =D26/C26 | F26: 32 | G26: 36 | H26: 38 | I26: 46 | J26: 147 | K26: =349978/1024
A27: Puzzle board | B27: 57 | C27: 2624 | D27: 974 | E27: =D27/C27 | F27: 26 | G27: 38 | H27: 40 | I27: 89 | J27: 343 | K27: =183170/1024
A29: Control check: the same screens with no screen reads by the test tool
A30: Check | B30: Frames | C30: Janky frames | D30: Janky % | E30: Median frame (ms) | F30: 99th pct (ms) | G30: Slow UI-thread frames
A31: Game Map, idle 20s (no screen reads) | B31: 1133 | C31: 1106 | D31: =C31/B31 | E31: 30 | F31: 46 | G31: 808
A32: Home, 20 swipes (no screen reads) | B32: 874 | C32: 286 | D32: =C32/B32 | E32: 24 | F32: 48 | G32: 49
A33: Home, idle 15s | B33: 210 | C33: 11 | D33: =C33/B33 | E33: 18 | F33: 61 | G33: 4
A35: The Game Map stays ~98% janky even when nothing is touched, so the slowdown is the map's own looping animations (pin pulse, floating spin button) running on the main thread, not the test tool. On a 60 Hz screen a frame must be ready in 16.7 ms; the map takes ~30 ms (about 33 fps).
A38: Sustained play: five full loops
A39: Frames drawn | B39: 81764
A40: Janky frames | B40: 46815
A41: Janky % | B41: =B40/B39
A42: Median frame (ms) | B42: 30
A43: 99th percentile (ms) | B43: 48
A44: Crash / freeze reports | B44: 0
A46: Loop | B46: Elapsed (s) | C46: Memory (PSS, MB)
A47: Start | B47: 0 | C47: =170450/1024
A48: After loop 1 | B48: 272 | C48: =149606/1024
...

Sheet Phone vs emulator
A1: Real phone vs emulator
A2: Every figure is a link to the measurement sheets.
A4: Measure | B4: Emulator (debug, 2 GB RAM) | C4: Real phone (release, vivo V17 Pro) | D4: Which is better
A5: Cold start (ms, average) | B5: ='Startup'!C10 | C5: ='Real phone'!B19 | D5: =IF(C5<B5,"Real phone",IF(C5>B5,"Emulator","Same"))
A6: Warm start (ms, average) | B6: ='Startup'!E10 | C6: ='Real phone'!C19 | D6: =IF(C6<B6,"Real phone",IF(C6>B6,"Emulator","Same"))
A7: Home: janky frames | B7: ='Per screen'!E5 | C7: ='Real phone'!E23 | D7: =IF(C7<B7,"Real phone",IF(C7>B7,"Emulator","Same"))
A8: Game Map: janky frames | B8: ='Per screen'!E6 | C8: ='Real phone'!E24 | D8: =IF(C8<B8,"Real phone",IF(C8>B8,"Emulator","Same"))
A9: Learn + dish page: janky frames | B9: ='Per screen'!E7 | C9: ='Real phone'!E25 | D9: =IF(C9<B9,"Real phone",IF(C9>B9,"Emulator","Same"))
A10: Pantry: janky frames | B10: ='Per screen'!E8 | C10: ='Real phone'!E26 | D10: =IF(C10<B10,"Real phone",IF(C10>B10,"Emulator","Same"))
A11: Puzzle board: janky frames | B11: ='Per screen'!E9 | C11: ='Real phone'!E27 | D11: =IF(C11<B11,"Real phone",IF(C11>B11,"Emulator","Same"))
A12: Sustained run: janky frames | B12: ='Sustained'!B5 | C12: ='Real phone'!B41 | D12: =IF(C12<B12,"Real phone",IF(C12>B12,"Emulator","Same"))
A13: Memory trend | B13: ='Sustained'!C21 | C13: ='Real phone'!C54
A15: Startup: the real phone is about 3.5x faster (release build, real storage). Smoothness: the real phone is much worse on animated screens. The emulator borrows the laptop's processor and graphics, which hid the Game Map's per-frame cost. Use the real-phone figures for the manuscript; the emulator remains useful for crash and memory-leak checks.

Sheet Per screen
A1: Frames and memory per screen
A2: dumpsys gfxinfo, reset before each screen. Janky = frame that missed its display deadline.
A4: Screen | B4: Seconds | C4: Frames | D4: Janky frames | E4: Janky % | F4: Median frame (ms) | G4: 90th pct (ms) | H4: 95th pct (ms) | I4: 99th pct (ms) | J4: Slow UI-thread frames | K4: Memory (PSS, MB)
A5: Home | B5: 26 | C5: 948 | D5: 41 | E5: =D5/C5 | F5: 18 | G5: 24 | H5: 29 | I5: 36 | J5: 4 | K5: =178342/1024
A6: Game Map | B6: 87 | C6: 5026 | D6: 66 | E6: =D6/C6 | F6: 23 | G6: 29 | H6: 32 | I6: 53 | J6: 39 | K6: =174899/1024
A7: Learn + dish page | B7: 64 | C7: 1318 | D7: 77 | E7: =D7/C7 | F7: 17 | G7: 26 | H7: 32 | I7: 57 | J7: 21 | K7: =235068/1024
A8: Pantry | B8: 40 | C8: 1558 | D8: 30 | E8: =D8/C8 | F8: 22 | G8: 27 | H8: 31 | I8: 53 | J8: 17 | K8: =307126/1024
A9: Puzzle board | B9: 52 | C9: 2451 | D9: 82 | E9: =D9/C9 | F9: 24 | G9: 34 | H9: 42 | I9: 69 | J9: 51 | K9: =191830/1024
A10: All screens | B10: =SUM(B5:B9) | C10: =SUM(C5:C9) | D10: =SUM(D5:D9) | E10: =D10/C10 | I10: =MAX(I5:I9) | K10: =MAX(K5:K9)
A12: Under ~10% janky frames generally feels smooth. Highest jank: Learn + dish page; slowest worst-case frames: Puzzle board (fast typing with tile animations); most memory: Pantry (many ingredient pictures).

Sheet Sustained
A1: Sustained play: five full loops through all five screens
A2: Fixed build, clean run (one script only).
A3: Frames drawn | B3: 57679
A4: Janky frames | B4: 1230
A5: Janky % | B5: =B4/B3
A6: Median frame (ms) | B6: 22
A7: 90th percentile (ms) | B7: 30
A8: 95th percentile (ms) | B8: 32
A9: 99th percentile (ms) | B9: 48
A11: Crash / freeze reports during the run | B11: 0
A13: Loop | B13: Elapsed (s) | C13: Memory (PSS, MB)
A14: Start | B14: 0 | C14: =173237/1024
A15: After loop 1 | B15: 286 | C15: =192365/1024
A16: After loop 2 | B16: 560 | C16: =198029/1024
A17: After loop 3 | B17: 833 | C17: =196037/1024
A18: After loop 4 | B18: 1099 | C18: =197042/1024
A19: After loop 5 | B19: 1366 | C19: =194990/1024
A21: Memory trend | C21: =IF(MAX(C15:C19)-MIN(C15:C19)<=15,"Flat (no leak)","Rising — check for a leak")
A22: Change from loop 1 to the last loop (MB) | C22: =C19-C15

Sheet Startup freezes
A1: Startup freezes (Android 'isn't responding' reports)
A3: # | B3: When | C3: Phone CPU busy | D3: System (kernel) share | E3: Android's reason | F3: Where the app was waiting
A4: 1 | B4: 2026-10-05 00:28:03.665 | C4: 96% | D4: 76% | E4: Process failed to complete startup | F4: Main thread waiting for a saved-settings file to load: ReelCatalogStore.warm (line 46), called from KusinaKodeApp.onCreate
A5: 2 | B5: 2026-10-05 00:38:47.057 | C5: 97% | D5: 74% | E5: Process failed to complete startup | F5: Main thread waiting for a saved-settings file to load: ReelCatalogStore.warm (line 46), called from KusinaKodeApp.onCreate
A7: When | C7: Both right after the emulator booted, while the phone was still settling.
A8: Likely cause | C8: A very busy phone, mostly the system itself (about 75% of CPU in the kernel), which points to memory being swapped to disk. The app's startup code was reading files on the main thread at that moment, so it could not draw its first screen.
A9: Fix (1.26, not yet released) | C9: Reading the reel list, creating notification channels and scheduling play reminders now happen on a background thread, so the first screen does not wait for them.
A10: Verification | C10: Unit tests pass. Notification channels confirmed. With the CPU maxed out, neither the old nor the fixed code froze, so the original freeze could not be recreated on demand; the fix removes the file reads Android caught, but it is not proven by this test.
A11: During normal play | C11: No freezes or crashes in the sustained run.

Sheet Server load
A1: Server load test (read-only, live API)
A2: 2026-10-05T01:56:28+00:00 to 2026-10-05T02:01:15+00:00 UTC. Simulated players fetch levels, leaderboard, ingredients, equipment and reels. Nothing written. Auto-stop at >5% errors or p95 > 10 s.
A4: Players at once | B4: Requests | C4: Requests / s | D4: Errors | E4: Error rate | F4: Average (s) | G4: Median (s) | H4: 90th pct (s) | I4: 95th pct (s) | J4: 99th pct (s) | K4: Slowest (s)
A5: 5 | B5: 237 | C5: =B5/60 | D5: 0 | E5: =D5/B5 | F5: 0.254 | G5: 0.247 | H5: 0.331 | I5: 0.368 | J5: 0.392 | K5: 0.442
A6: 10 | B6: 459 | C6: =B6/60 | D6: 0 | E6: =D6/B6 | F6: 0.314 | G6: 0.275 | H6: 0.423 | I6: 0.483 | J6: 0.618 | K6: 5.385
A7: 20 | B7: 747 | C7: =B7/60 | D7: 0 | E7: =D7/B7 | F7: 0.56 | G7: 0.448 | H7: 0.954 | I7: 1.21 | J7: 1.758 | K7: 5.863
A8: 40 | B8: 873 | C8: =B8/60 | D8: 0 | E8: =D8/B8 | F8: 1.6 | G8: 1.48 | H8: 2.716 | I8: 3.128 | J8: 4.257 | K8: 7.372
A9: Total | B9: =SUM(B5:B8) | D9: =SUM(D5:D8) | E9: =D9/B9
A11: Per endpoint at 40 players
A12: Endpoint | B12: Requests | C12: Average (s) | D12: 95th pct (s) | E12: Errors
A13: get_levels.php | B13: 295 | C13: 1.548 | D13: 2.716 | E13: 0
A14: get_leaderboard.php | B14: 203 | C14: 2.05 | D14: 3.883 | E14: 0
A15: get_ingredients.php | B15: 188 | C15: 1.197 | D15: 1.965 | E15: 0
A16: get_equipment.php | B16: 97 | C16: 1.32 | D16: 2.272 | E16: 0
A17: reels/list.php | B17: 90 | C17: 1.902 | D17: 3.509 | E17: 0
A19: No errors at any stage. Response time grew from ~0.25 s (5 players) to ~1.6 s average (40 players), and throughput levelled off near 15 requests/s: the system was saturating. Azure metrics (next sheet) place the limit in the database. Separately, the first request after the server sat idle took 5.4 s (wake-up), then ~0.23 s.

Sheet Azure metrics
A1: Azure metrics during the server load test
A2: Per minute, from Azure Monitor. VM = vm-kusinakode-api; database = sql-kusinakode/kusinakode (Basic tier).
A4: Minute (UTC) | B4: Test stage | C4: VM CPU avg % | D4: VM CPU max % | E4: VM free memory (MB) | F4: DB load avg % (DTU) | G4: DB load max % (DTU)
A5: 01:56 | B5: idle | C5: 0.1 | D5: 0.1 | E5: =446693376.0/1048576 | F5: 0 | G5: 0
A6: 01:57 | B6: warm-up / 5 players | C6: 1 | D6: 1.5 | E6: =446169088.0/1048576 | F6: 7.2 | G6: 20
A7: 01:58 | B7: 10 players | C7: 3.2 | D7: 3.6 | E7: =447217664.0/1048576 | F7: 16.8 | G7: 28
A8: 01:59 | B8: 20 players | C8: 6.9 | D8: 7.3 | E8: =445120512.0/1048576 | F8: 29.5 | G8: 44
A9: 02:00 | B9: 40 players | C9: 9.7 | D9: 11.8 | E9: =441450496.0/1048576 | F9: 57.8 | G9: 63
A10: 02:01 | B10: 40 players (end) | C10: n/a | D10: n/a | E10: n/a | F10: 68 | G10: 91
A11: Peak | D11: =MAX(D5:D10) | G11: =MAX(G5:G10)
A13: The API server's CPU stayed at or under ~12% while the Basic-tier database reached 91% at 40 players. The database is the bottleneck; past roughly 50 simultaneous players it would queue requests. Raising the database tier (e.g. Basic to Standard S1) is a setting in the Azure portal. VM minutes after 02:00 had not been published yet when collected.
